2021-12-23 06:08:02,169:DEBUG:certbot.main:certbot version: 0.40.0
2021-12-23 06:08:02,170:DEBUG:certbot.main:Arguments: ['-d', 'entrypoint.ga', '--manual', '--work-dir', './', '--config-dir', './', '--logs-dir', './', '--preferred-challenges', 'dns', '--manual-auth-hook', './auth.sh']
2021-12-23 06:08:02,170:DEBUG:certbot.main:Discovered plugins: PluginsRegistry(PluginEntryPoint#manual,PluginEntryPoint#nginx,PluginEntryPoint#null,PluginEntryPoint#standalone,PluginEntryPoint#webroot)
2021-12-23 06:08:02,186:DEBUG:certbot.log:Root logging level set at 20
2021-12-23 06:08:02,186:INFO:certbot.log:Saving debug log to /home/ubuntu/hyper-web-relay/live/letsencrypt.log
2021-12-23 06:08:02,189:DEBUG:certbot.plugins.selection:Requested authenticator manual and installer None
2021-12-23 06:08:02,189:DEBUG:certbot.plugins.util:Failed to find executable ./auth.sh in PATH: /home/ubuntu/.nvm/versions/node/v12.22.3/bin:/usr/local/sbin:/usr/local/bin:/usr/sbin:/usr/bin:/sbin:/bin:/usr/games:/usr/local/games:/snap/bin
2021-12-23 06:08:02,190:DEBUG:certbot.log:Exiting abnormally:
Traceback (most recent call last):
  File "/usr/bin/certbot", line 11, in <module>
    load_entry_point('certbot==0.40.0', 'console_scripts', 'certbot')()
  File "/usr/lib/python3/dist-packages/certbot/main.py", line 1382, in main
    return config.func(config, plugins)
  File "/usr/lib/python3/dist-packages/certbot/main.py", line 1244, in certonly
    installer, auth = plug_sel.choose_configurator_plugins(config, plugins, "certonly")
  File "/usr/lib/python3/dist-packages/certbot/plugins/selection.py", line 228, in choose_configurator_plugins
    authenticator = pick_authenticator(config, req_auth, plugins)
  File "/usr/lib/python3/dist-packages/certbot/plugins/selection.py", line 38, in pick_authenticator
    return pick_plugin(
  File "/usr/lib/python3/dist-packages/certbot/plugins/selection.py", line 105, in pick_plugin
    verified.prepare()
  File "/usr/lib/python3/dist-packages/certbot/plugins/disco.py", line 252, in prepare
    return [plugin_ep.prepare() for plugin_ep in six.itervalues(self._plugins)]
  File "/usr/lib/python3/dist-packages/certbot/plugins/disco.py", line 252, in <listcomp>
    return [plugin_ep.prepare() for plugin_ep in six.itervalues(self._plugins)]
  File "/usr/lib/python3/dist-packages/certbot/plugins/disco.py", line 130, in prepare
    self._initialized.prepare()
  File "/usr/lib/python3/dist-packages/certbot/plugins/manual.py", line 91, in prepare
    self._validate_hooks()
  File "/usr/lib/python3/dist-packages/certbot/plugins/manual.py", line 99, in _validate_hooks
    hooks.validate_hook(hook, hook_prefix)
  File "/usr/lib/python3/dist-packages/certbot/hooks.py", line 57, in validate_hook
    raise errors.HookCommandNotFound(msg)
certbot.errors.HookCommandNotFound: Unable to find manual-auth-hook command ./auth.sh in the PATH.
(PATH is /home/ubuntu/.nvm/versions/node/v12.22.3/bin:/usr/local/sbin:/usr/local/bin:/usr/sbin:/usr/bin:/sbin:/bin:/usr/games:/usr/local/games:/snap/bin)
